try {
    anotherFuntion();
} catch (error) {
    console.log('Esto es un error!');
}